2025-03-31 22:41:58 INFO     Finished wandb init.
README.md: 100%|██████████████████████████████████████████████████████████████████████████████████████████████████████████████████████████████████████████████████████████████████████████████████████████| 720/720 [00:00<?, ?B/s]
C:\Users\nikos\anaconda3\envs\nllSAR\Lib\site-packages\huggingface_hub\file_download.py:144: UserWarning: `huggingface_hub` cache-system uses symlinks by default to efficiently store duplicated files but your machine does not support them in C:\Users\nikos\.cache\huggingface\hub\datasets--TimoImhof--TriviaQA-in-SQuAD-format. Caching files will still work but in a degraded version that might require more space on your disk. This warning can be disabled by setting the `HF_HUB_DISABLE_SYMLINKS_WARNING` environment variable. For more details, see https://huggingface.co/docs/huggingface_hub/how-to-cache#limitations.
To support symlinks on Windows, you either need to activate Developer Mode or to run Python as an administrator. In order to activate developer mode, see this article: https://docs.microsoft.com/en-us/windows/apps/get-started/enable-your-device-for-development
  warnings.warn(message)
(…)-00000-of-00001-6ecbad160e20a7c4.parquet: 100%|████████████████████████████████████████████████████████████████████████████████████████████████████████████████████████████████████████████| 13.2M/13.2M [00:00<00:00, 17.7MB/s]
(…)-00000-of-00001-532a23f957ec580c.parquet: 100%|████████████████████████████████████████████████████████████████████████████████████████████████████████████████████████████████████████████| 14.4M/14.4M [00:00<00:00, 19.7MB/s]
(…)-00000-of-00001-52c5d4e11108e7a6.parquet: 100%|████████████████████████████████████████████████████████████████████████████████████████████████████████████████████████████████████████████| 13.1M/13.1M [00:00<00:00, 19.9MB/s]
Generating modified_100_percent split: 100%|██████████████████████████████████████████████████████████████████████████████████████████████████████████████████████████████████████| 15368/15368 [00:00<00:00, 199906.54 examples/s]
Generating modified_30_percent split: 100%|███████████████████████████████████████████████████████████████████████████████████████████████████████████████████████████████████████| 15368/15368 [00:00<00:00, 320067.45 examples/s]
Generating unmodified split: 100%|████████████████████████████████████████████████████████████████████████████████████████████████████████████████████████████████████████████████| 15368/15368 [00:00<00:00, 323303.88 examples/s]
2025-03-31 22:42:07 INFO     Train dataset: Dataset({
    features: ['id', 'question', 'context', 'answers'],
    num_rows: 12294
})
2025-03-31 22:42:10 INFO     Prompt is: Answer the following question as briefly as possible.
Question: In April, which sportsman married his childhood sweetheart Kim Sears?
Answer: andy murray

Question: From the Latin for argentum, which element, with an atomic number of 47, uses the symbol Ag?
Answer: silver

Question: In which English city will you find the Ashmolean museum?
Answer: oxford

Question: In which city was John Lennon murdered?
Answer: new york

Question: What was Groucho Marx's real first name?
Answer: julius


Traceback (most recent call last):
  File "C:\Users\nikos\anaconda3\envs\nllSAR\Lib\site-packages\huggingface_hub\utils\_http.py", line 409, in hf_raise_for_status
    response.raise_for_status()
  File "C:\Users\nikos\anaconda3\envs\nllSAR\Lib\site-packages\requests\models.py", line 1024, in raise_for_status
    raise HTTPError(http_error_msg, response=self)
requests.exceptions.HTTPError: 404 Client Error: Not Found for url: https://huggingface.co/huggyllama/Llama-3.2-1B/resolve/main/tokenizer_config.json

The above exception was the direct cause of the following exception:

Traceback (most recent call last):
  File "C:\Users\nikos\anaconda3\envs\nllSAR\Lib\site-packages\transformers\utils\hub.py", line 403, in cached_file
    resolved_file = hf_hub_download(
                    ^^^^^^^^^^^^^^^^
  File "C:\Users\nikos\anaconda3\envs\nllSAR\Lib\site-packages\huggingface_hub\utils\_validators.py", line 114, in _inner_fn
    return fn(*args, **kwargs)
           ^^^^^^^^^^^^^^^^^^^
  File "C:\Users\nikos\anaconda3\envs\nllSAR\Lib\site-packages\huggingface_hub\file_download.py", line 961, in hf_hub_download
    return _hf_hub_download_to_cache_dir(
           ^^^^^^^^^^^^^^^^^^^^^^^^^^^^^^
  File "C:\Users\nikos\anaconda3\envs\nllSAR\Lib\site-packages\huggingface_hub\file_download.py", line 1068, in _hf_hub_download_to_cache_dir
    _raise_on_head_call_error(head_call_error, force_download, local_files_only)
  File "C:\Users\nikos\anaconda3\envs\nllSAR\Lib\site-packages\huggingface_hub\file_download.py", line 1596, in _raise_on_head_call_error
    raise head_call_error
  File "C:\Users\nikos\anaconda3\envs\nllSAR\Lib\site-packages\huggingface_hub\file_download.py", line 1484, in _get_metadata_or_catch_error
    metadata = get_hf_file_metadata(
               ^^^^^^^^^^^^^^^^^^^^^
  File "C:\Users\nikos\anaconda3\envs\nllSAR\Lib\site-packages\huggingface_hub\utils\_validators.py", line 114, in _inner_fn
    return fn(*args, **kwargs)
           ^^^^^^^^^^^^^^^^^^^
  File "C:\Users\nikos\anaconda3\envs\nllSAR\Lib\site-packages\huggingface_hub\file_download.py", line 1401, in get_hf_file_metadata
    r = _request_wrapper(
        ^^^^^^^^^^^^^^^^^
  File "C:\Users\nikos\anaconda3\envs\nllSAR\Lib\site-packages\huggingface_hub\file_download.py", line 285, in _request_wrapper
    response = _request_wrapper(
               ^^^^^^^^^^^^^^^^^
  File "C:\Users\nikos\anaconda3\envs\nllSAR\Lib\site-packages\huggingface_hub\file_download.py", line 309, in _request_wrapper
    hf_raise_for_status(response)
  File "C:\Users\nikos\anaconda3\envs\nllSAR\Lib\site-packages\huggingface_hub\utils\_http.py", line 459, in hf_raise_for_status
    raise _format(RepositoryNotFoundError, message, response) from e
huggingface_hub.errors.RepositoryNotFoundError: 404 Client Error. (Request ID: Root=1-67eafe22-67a0d6b11f4d5b671dd5b201;918dc79c-f3e9-4dfb-b518-e2d1f1b054c9)

Repository Not Found for url: https://huggingface.co/huggyllama/Llama-3.2-1B/resolve/main/tokenizer_config.json.
Please make sure you specified the correct `repo_id` and `repo_type`.
If you are trying to access a private or gated repo, make sure you are authenticated. For more details, see https://huggingface.co/docs/huggingface_hub/authentication

The above exception was the direct cause of the following exception:

Traceback (most recent call last):
  File "C:\Users\nikos\PycharmProjects\nllSAR\src\generate_answers.py", line 263, in <module>
    main(args)
  File "C:\Users\nikos\PycharmProjects\nllSAR\src\generate_answers.py", line 89, in main
    model = utils.init_model(args)
            ^^^^^^^^^^^^^^^^^^^^^^
  File "C:\Users\nikos\PycharmProjects\nllSAR\src\utils\utils.py", line 278, in init_model
    model = HuggingfaceModel(
            ^^^^^^^^^^^^^^^^^
  File "C:\Users\nikos\PycharmProjects\nllSAR\src\models\huggingface_models.py", line 113, in __init__
    self.tokenizer = AutoTokenizer.from_pretrained(
                     ^^^^^^^^^^^^^^^^^^^^^^^^^^^^^^
  File "C:\Users\nikos\anaconda3\envs\nllSAR\Lib\site-packages\transformers\models\auto\tokenization_auto.py", line 857, in from_pretrained
    tokenizer_config = get_tokenizer_config(pretrained_model_name_or_path, **kwargs)
                       ^^^^^^^^^^^^^^^^^^^^^^^^^^^^^^^^^^^^^^^^^^^^^^^^^^^^^^^^^^^^^
  File "C:\Users\nikos\anaconda3\envs\nllSAR\Lib\site-packages\transformers\models\auto\tokenization_auto.py", line 689, in get_tokenizer_config
    resolved_config_file = cached_file(
                           ^^^^^^^^^^^^
  File "C:\Users\nikos\anaconda3\envs\nllSAR\Lib\site-packages\transformers\utils\hub.py", line 426, in cached_file
    raise EnvironmentError(
OSError: huggyllama/Llama-3.2-1B is not a local folder and is not a valid model identifier listed on 'https://huggingface.co/models'
If this is a private repository, make sure to pass a token having permission to this repo either by logging in with `huggingface-cli login` or by passing `token=<your_token>`
